<?xml version="1.0" encoding="utf-8"?>
<!-- This URDF was automatically created by SolidWorks to URDF Exporter! Originally created by Stephen Brawner (brawner@gmail.com) 
     Commit Version: 1.6.0-4-g7f85cfe  Build Version: 1.6.7995.38578
     For more information, please see http://wiki.ros.org/sw_urdf_exporter -->
<robot xmlns:xacro="http://www.ros.org/wiki/xacro" name="robot_description">
  <xacro:arg name="robot_name" default="robot"/>
  
	<xacro:macro name="robot_spawn" params="robot_name:=robot_0">
    <xacro:arg name="robot_name" default="${str(robot_name)}"/>
    <xacro:include filename="$(find robot_description)/urdf/robot_description.gazebo.xml"/>
	</xacro:macro>
  <xacro:robot_spawn robot_name="$(arg robot_name)"/>

  <link name="dummy_base_link"/>

  <joint name="dummy_base_joint" type="fixed">
    <parent link="dummy_base_link"/>
    <child link="base_link"/>
    <origin xyz="0 0 0.06" rpy="0 0 0"/>
  </joint>

  <link
    name="base_link">
    <inertial>
      <origin
        xyz="0.0054863 0.00077565 0.0033605"
        rpy="0 0 0" />
      <mass
        value="6.57854" />
      <inertia
        ixx="0.00065747"
        ixy="3.6159E-08"
        ixz="4.3207E-07"
        iyy="0.0006972"
        iyz="-1.4438E-08"
        izz="0.0013013" />
    </inertial>
    <visual>
      <origin
        xyz="0 0 0"
        rpy="0 0 0" />
      <geometry>
        <mesh
          filename="package://robot_description/meshes/base_link.STL" />
      </geometry>
      <material
        name="">
        <color
          rgba="0.792156862745098 0.819607843137255 0.933333333333333 1" />
      </material>
    </visual>
    <collision>
      <origin
        xyz="0 0 0"
        rpy="0 0 0" />
      <geometry>
        <mesh
          filename="package://robot_description/meshes/base_link.STL" />
      </geometry>
    </collision>
  </link>
  <link
    name="lidar">
    <inertial>
      <origin
        xyz="0.0015853 0.0011546 0.0053644"
        rpy="0 0 0" />
      <mass
        value="0.522081" />
      <inertia
        ixx="7.2125E-06"
        ixy="-1.0423E-07"
        ixz="-1.2667E-08"
        iyy="7.4427E-06"
        iyz="-9.3223E-09"
        izz="1.3741E-05" />
    </inertial>
    <visual>
      <origin
        xyz="0 0 0"
        rpy="0 0 0" />
      <geometry>
        <mesh
          filename="package://robot_description/meshes/lidar.STL" />
      </geometry>
      <material
        name="">
        <color
          rgba="0.43921568627451 0.43921568627451 0.43921568627451 1" />
      </material>
    </visual>
    <collision>
      <origin
        xyz="0 0 0"
        rpy="0 0 0" />
      <geometry>
        <mesh
          filename="package://robot_description/meshes/lidar.STL" />
      </geometry>
    </collision>
  </link>
  <joint
    name="lidar_jl"
    type="fixed">
    <origin
      xyz="0.000149 0.00018885 0.0763"
      rpy="0 0 0" />
    <parent
      link="base_link" />
    <child
      link="lidar" />
    <axis
      xyz="0 0 -1" />
    <limit
      effort="100"
      velocity="100" />
  </joint>
  <link
    name="left_wheel">
    <inertial>
      <origin
        xyz="-2.2262E-05 0.00025851 2.273E-05"
        rpy="0 0 0" />
      <mass
        value="0.67903" />
      <inertia
        ixx="2.82E-05"
        ixy="-4.276E-10"
        ixz="-2.0288E-08"
        iyy="4.608E-05"
        iyz="1.5667E-10"
        izz="2.8201E-05" />
    </inertial>
    <visual>
      <origin
        xyz="0 0 0"
        rpy="0 0 0" />
      <geometry>
        <mesh
          filename="package://robot_description/meshes/left_wheel.STL" />
      </geometry>
      <material
        name="">
        <color
          rgba="0.752941176470588 0.752941176470588 0.752941176470588 1" />
      </material>
    </visual>
    <collision>
      <origin
        xyz="0 0 0"
        rpy="0 0 0" />
      <geometry>
        <mesh
          filename="package://robot_description/meshes/left_wheel.STL" />
      </geometry>
    </collision>
  </link>
  <joint
    name="left_wheel_jl"
    type="continuous">
    <origin
      xyz="-0.000275319332503843 0.105 -0.0266929866933577"
      rpy="0 0 0" />
    <parent
      link="base_link" />
    <child
      link="left_wheel" />
    <axis
      xyz="0 -1 0" />
    <limit
      effort="100"
      velocity="100" />
  </joint>
  <link
    name="right_wheel">
    <inertial>
      <origin
        xyz="-1.4633E-05 -0.00025851 -2.8251E-05"
        rpy="0 0 0" />
      <mass
        value="0.67903" />
      <inertia
        ixx="2.8189E-05"
        ixy="3.6301E-10"
        ixz="1.6521E-08"
        iyy="4.608E-05"
        iyz="2.7497E-10"
        izz="2.8212E-05" />
    </inertial>
    <visual>
      <origin
        xyz="0 0 0"
        rpy="0 0 0" />
      <geometry>
        <mesh
          filename="package://robot_description/meshes/right_wheel.STL" />
      </geometry>
      <material
        name="">
        <color
          rgba="0.752941176470588 0.752941176470588 0.752941176470588 1" />
      </material>
    </visual>
    <collision>
      <origin
        xyz="0 0 0"
        rpy="0 0 0" />
      <geometry>
        <mesh
          filename="package://robot_description/meshes/right_wheel.STL" />
      </geometry>
    </collision>
  </link>
  <joint
    name="right_wheel_jl"
    type="continuous">
    <origin
      xyz="-0.000172826687894733 -0.105 -0.0273779601243553"
      rpy="0 0 0" />
    <parent
      link="base_link" />
    <child
      link="right_wheel" />
    <axis
      xyz="0 1 0" />
    <limit
      effort="100"
      velocity="100" />
  </joint>
  <link
    name="bumper">
    <inertial>
      <origin
        xyz="0.0296 -0.0052479 0.033914"
        rpy="0 0 0" />
      <mass
        value="0.0140453" />
      <inertia
        ixx="1.7497E-07"
        ixy="4.9599E-09"
        ixz="4.6788E-09"
        iyy="1.4324E-07"
        iyz="1.4367E-09"
        izz="2.7481E-07" />
    </inertial>
    <visual>
      <origin
        xyz="0 0 0"
        rpy="0 0 0" />
      <geometry>
        <mesh
          filename="package://robot_description/meshes/bumper.STL" />
      </geometry>
      <material
        name="">
        <color
          rgba="0.75294 0.75294 0.75294 1" />
      </material>
    </visual>
    <collision name="bumper_collision">
      <origin
        xyz="0 0 0"
        rpy="0 0 0" />
      <geometry>
        <mesh
          filename="package://robot_description/meshes/bumper.STL" />
      </geometry>
    </collision>
  </link>
  <joint
    name="bumper_jl"
    type="fixed">
    <origin
      xyz="0 0 0"
      rpy="0 0 0" />
    <parent
      link="base_link" />
    <child
      link="bumper" />
    <axis
      xyz="0 0 0" />
  </joint>
</robot>